This is a testharness.js-based test.
Harness Error. harness_status.status = 1 , harness_status.message = Uncaught Error: Received unknown message
FAIL Tests that when timeout is non-zero, the success callback is called as expected. promise_test: Unhandled rejection with value: "Error callback invoked unexpectedly"
Harness: the test ran to completion.

